<?xml version="1.0" ?>
<!-- =================================================================================== -->
<!-- |    This document was autogenerated by xacro from panda_arm.urdf.xacro           | -->
<!-- |    EDITING THIS FILE BY HAND IS NOT RECOMMENDED                                 | -->
<!-- =================================================================================== -->
<robot name="panda" xmlns:xacro="http://www.ros.org/wiki/xacro">
  <link name="world"/>
  <joint name="world_to_r_robot" type="fixed">
    <origin rpy="0 0 0" xyz="0 0 0"/>
    <parent link="world"/>
    <child link="instrument1"/>
    <axis xyz="0 0 0"/>
  </joint>
  <link name="instrument1">
    <visual>
      <geometry>
        <mesh filename="package://franka_description/meshes/instrument/instrument1.stl"/>
      </geometry>
      <material name="">
        <color rgba="1 0.93 0.54 1" />
      </material>
    </visual>
    <collision>
      <geometry>
        <mesh filename="package://franka_description/meshes/instrument/instrument1.stl"/>
      </geometry>
    </collision>
  </link>

  <link name="temp">
  </link>
  <joint name="temp_joint" type="fixed">
    <origin rpy="-0.0117919678 0 0" xyz="0 -0.09102 0.36"/>
    <parent link="instrument1"/>
    <child link="temp"/>
    <axis xyz="0 0 0"/>
  </joint>


  <link name="instrument2">
    <visual>
      <geometry>
        <mesh filename="package://franka_description/meshes/instrument/2.stl"/>
      </geometry>
      <material name="">
        <color rgba="1 0.93 0.54 1" />
      </material>
    </visual>
    <collision>
      <geometry>
        <mesh filename="package://franka_description/meshes/instrument/2.stl"/>
      </geometry>
    </collision>
  </link>
  <joint name="instrument1_to_2" type="revolute">
    <origin rpy="0 0 0" xyz="0 0 0"/>
    <parent link="temp"/>
    <child link="instrument2"/>
    <axis xyz="0 0 1"/>
    <limit effort="12" lower="-3.14" upper="3.14" velocity="2.6100"/>
  </joint>

  <link name="instrument3">
    <visual>
      <geometry>
        <mesh filename="package://franka_description/meshes/instrument/3.stl"/>
      </geometry>
      <material name="">
        <color rgba="1 0.93 0.54 1" />
      </material>
    </visual>
    <collision>
      <geometry>
        <mesh filename="package://franka_description/meshes/instrument/3.stl"/>
      </geometry>
    </collision>
  </link>
  <joint name="instrument2_to_3" type="revolute">
    <origin rpy="0 0 0" xyz="0 0 0.009"/>
    <parent link="instrument2"/>
    <child link="instrument3"/>
    <axis xyz="1 0 0"/>
    <limit effort="12" lower="-1.5" upper="1.5" velocity="2.6100"/>
  </joint>

  <link name="instrument4">
    <visual>
      <geometry>
        <mesh filename="package://franka_description/meshes/instrument/4.stl"/>
      </geometry>
      <material name="">
        <color rgba="1 0.93 0.54 1" />
      </material>
    </visual>
    <collision>
      <geometry>
        <mesh filename="package://franka_description/meshes/instrument/4.stl"/>
      </geometry>
    </collision>
  </link>
  <joint name="instrument3_to_4" type="revolute">
    <origin rpy="0 0 0" xyz="0 0 0.009"/>
    <parent link="instrument3"/>
    <child link="instrument4"/>
    <axis xyz="0 1 0"/>
    <limit effort="12" lower="-1.5" upper="1.5" velocity="2.6100"/>
  </joint>

  <link name="r_tool"/>
  <joint name="instrument4_to_tool" type="fixed">
    <origin rpy="0 0 0" xyz="0 0 0.022"/>
    <parent link="instrument4"/>
    <child link="r_tool"/>
    <axis xyz="0 0 0"/>
  </joint>

</robot>

