<?xml version="1.0" ?>
<!-- =================================================================================== -->
<!-- |    This document was autogenerated by xacro from panda_arm.urdf.xacro           | -->
<!-- |    EDITING THIS FILE BY HAND IS NOT RECOMMENDED                                 | -->
<!-- =================================================================================== -->
<robot name="panda" xmlns:xacro="http://www.ros.org/wiki/xacro">
  <link name="world"/>
  <joint name="world_to_robot1" type="fixed">
    <origin rpy="0 0 0" xyz="0 0 0"/>
    <parent link="world"/>
    <child link="panda1_link0"/>
    <axis xyz="0 0 0"/>
  </joint>
  <link name="panda1_link0">
    <visual>
      <geometry>
        <mesh filename="package://franka_description/meshes/visual/link0.dae"/>
      </geometry>
    </visual>
    <collision>
      <geometry>
        <mesh filename="package://franka_description/meshes/collision/link0.stl"/>
      </geometry>
    </collision>
  </link>
  <link name="panda1_link1">
    <visual>
      <geometry>
        <mesh filename="package://franka_description/meshes/visual/link1.dae"/>
      </geometry>
    </visual>
    <collision>
      <geometry>
        <mesh filename="package://franka_description/meshes/collision/link1.stl"/>
      </geometry>
    </collision>
  </link>
  <joint name="franka1_panda_joint1" type="revolute">
    <safety_controller k_position="100.0" k_velocity="40.0" soft_lower_limit="-2.8973" soft_upper_limit="2.8973"/>
    <origin rpy="0 0 0" xyz="0 0 0.333"/>
    <parent link="panda1_link0"/>
    <child link="panda1_link1"/>
    <axis xyz="0 0 1"/>
    <limit effort="87" lower="-2.8973" upper="2.8973" velocity="2.1750"/>
  </joint>
  <link name="panda1_link2">
    <visual>
      <geometry>
        <mesh filename="package://franka_description/meshes/visual/link2.dae"/>
      </geometry>
    </visual>
    <collision>
      <geometry>
        <mesh filename="package://franka_description/meshes/collision/link2.stl"/>
      </geometry>
    </collision>
  </link>
  <joint name="franka1_panda_joint2" type="revolute">
    <safety_controller k_position="100.0" k_velocity="40.0" soft_lower_limit="-1.7628" soft_upper_limit="1.7628"/>
    <origin rpy="-1.57079632679 0 0" xyz="0 0 0"/>
    <parent link="panda1_link1"/>
    <child link="panda1_link2"/>
    <axis xyz="0 0 1"/>
    <limit effort="87" lower="-1.7628" upper="1.7628" velocity="2.1750"/>
  </joint>
  <link name="panda1_link3">
    <visual>
      <geometry>
        <mesh filename="package://franka_description/meshes/visual/link3.dae"/>
      </geometry>
    </visual>
    <collision>
      <geometry>
        <mesh filename="package://franka_description/meshes/collision/link3.stl"/>
      </geometry>
    </collision>
  </link>
  <joint name="franka1_panda_joint3" type="revolute">
    <safety_controller k_position="100.0" k_velocity="40.0" soft_lower_limit="-2.8973" soft_upper_limit="2.8973"/>
    <origin rpy="1.57079632679 0 0" xyz="0 -0.316 0"/>
    <parent link="panda1_link2"/>
    <child link="panda1_link3"/>
    <axis xyz="0 0 1"/>
    <limit effort="87" lower="-2.8973" upper="2.8973" velocity="2.1750"/>
  </joint>
  <link name="panda1_link4">
    <visual>
      <geometry>
        <mesh filename="package://franka_description/meshes/visual/link4.dae"/>
      </geometry>
    </visual>
    <collision>
      <geometry>
        <mesh filename="package://franka_description/meshes/collision/link4.stl"/>
      </geometry>
    </collision>
  </link>
  <joint name="franka1_panda_joint4" type="revolute">
    <safety_controller k_position="100.0" k_velocity="40.0" soft_lower_limit="-3.0718" soft_upper_limit="-0.0698"/>
    <origin rpy="1.57079632679 0 0" xyz="0.0825 0 0"/>
    <parent link="panda1_link3"/>
    <child link="panda1_link4"/>
    <axis xyz="0 0 1"/>
    <limit effort="87" lower="-3.0718" upper="-0.0698" velocity="2.1750"/>
  </joint>
  <link name="panda1_link5">
    <visual>
      <geometry>
        <mesh filename="package://franka_description/meshes/visual/link5.dae"/>
      </geometry>
    </visual>
    <collision>
      <geometry>
        <mesh filename="package://franka_description/meshes/collision/link5.stl"/>
      </geometry>
    </collision>
  </link>
  <joint name="franka1_panda_joint5" type="revolute">
    <safety_controller k_position="100.0" k_velocity="40.0" soft_lower_limit="-2.8973" soft_upper_limit="2.8973"/>
    <origin rpy="-1.57079632679 0 0" xyz="-0.0825 0.384 0"/>
    <parent link="panda1_link4"/>
    <child link="panda1_link5"/>
    <axis xyz="0 0 1"/>
    <limit effort="12" lower="-2.8973" upper="2.8973" velocity="2.6100"/>
  </joint>
  <link name="panda1_link6">
    <visual>
      <geometry>
        <mesh filename="package://franka_description/meshes/visual/link6.dae"/>
      </geometry>
    </visual>
    <collision>
      <geometry>
        <mesh filename="package://franka_description/meshes/collision/link6.stl"/>
      </geometry>
    </collision>
  </link>
  <joint name="franka1_panda_joint6" type="revolute">
    <safety_controller k_position="100.0" k_velocity="40.0" soft_lower_limit="-0.0175" soft_upper_limit="3.7525"/>
    <origin rpy="1.57079632679 0 0" xyz="0 0 0"/>
    <parent link="panda1_link5"/>
    <child link="panda1_link6"/>
    <axis xyz="0 0 1"/>
    <limit effort="12" lower="-0.0175" upper="3.7525" velocity="2.6100"/>
  </joint>
  <link name="panda1_link7">
    <visual>
      <geometry>
        <mesh filename="package://franka_description/meshes/visual/link7.dae"/>
      </geometry>
    </visual>
    <collision>
      <geometry>
        <mesh filename="package://franka_description/meshes/collision/link7.stl"/>
      </geometry>
    </collision>
  </link>
  <joint name="franka1_panda_joint7" type="revolute">
    <safety_controller k_position="100.0" k_velocity="40.0" soft_lower_limit="-2.8973" soft_upper_limit="2.8973"/>
    <origin rpy="1.57079632679 0 0" xyz="0.088 0 0"/>
    <parent link="panda1_link6"/>
    <child link="panda1_link7"/>
    <axis xyz="0 0 1"/>
    <limit effort="12" lower="-2.8973" upper="2.8973" velocity="2.6100"/>
  </joint>
  <link name="panda1_link8"/>
  <joint name="franka_panda_joint8" type="fixed">
    <origin rpy="0 0 0" xyz="0 0 0.107"/>
    <parent link="panda1_link7"/>
    <child link="panda1_link8"/>
    <axis xyz="0 0 0"/>
  </joint>
  <link name="ee1_link"/>
  <joint name="franka1_panda8_to_ee" type="fixed">
    <origin rpy="0 0 0.78539815" xyz="0 0 0"/>
    <parent link="panda1_link8"/>
    <child link="ee1_link"/>
    <axis xyz="0 0 0"/>
  </joint>
  <link name="franka1_instrument1">
    <visual>
      <geometry>
        <mesh filename="package://franka_description/meshes/instrument/instrument1.stl"/>
      </geometry>
      <material name="">
        <color rgba="1 0.93 0.54 1" />
      </material>
    </visual>
    <collision>
      <geometry>
        <mesh filename="package://franka_description/meshes/instrument/instrument1.stl"/>
      </geometry>
    </collision>
  </link>
  <joint name="franka1_ee_to_instrument1" type="fixed">
    <origin rpy="0 0 0" xyz="0 0 0"/>
    <parent link="ee1_link"/>
    <child link="franka1_instrument1"/>
    <axis xyz="0 0 0"/>
  </joint>
  <link name="franka1_instrument2">
    <visual>
      <geometry>
        <mesh filename="package://franka_description/meshes/instrument/2.stl"/>
      </geometry>
      <material name="">
        <color rgba="1 0.93 0.54 1" />
      </material>
    </visual>
    <collision>
      <geometry>
        <mesh filename="package://franka_description/meshes/instrument/2.stl"/>
      </geometry>
    </collision>
  </link>
  <joint name="franka1_instrument1_to_2" type="revolute">
    <origin rpy="-0.0117919678 0 0" xyz="0 -0.09102 0.36"/>
    <parent link="franka1_instrument1"/>
    <child link="franka1_instrument2"/>
    <axis xyz="0 0 1"/>
    <limit effort="12" lower="-3.14" upper="3.14" velocity="2.6100"/>
  </joint>
  <link name="franka1_instrument3">
    <visual>
      <geometry>
        <mesh filename="package://franka_description/meshes/instrument/3.stl"/>
      </geometry>
      <material name="">
        <color rgba="1 0.93 0.54 1" />
      </material>
    </visual>
    <collision>
      <geometry>
        <mesh filename="package://franka_description/meshes/instrument/3.stl"/>
      </geometry>
    </collision>
  </link>
  <joint name="franka1_instrument2_to_3" type="revolute">
    <origin rpy="0 0 0" xyz="0 0 0.009"/>
    <parent link="franka1_instrument2"/>
    <child link="franka1_instrument3"/>
    <axis xyz="1 0 0"/>
    <limit effort="12" lower="-1.5" upper="1.5" velocity="2.6100"/>
  </joint>
  <link name="franka1_instrument4">
    <visual>
      <geometry>
        <mesh filename="package://franka_description/meshes/instrument/4.stl"/>
      </geometry>
      <material name="">
        <color rgba="1 0.93 0.54 1" />
      </material>
    </visual>
    <collision>
      <geometry>
        <mesh filename="package://franka_description/meshes/instrument/4.stl"/>
      </geometry>
    </collision>
  </link>
  <joint name="franka1_instrument3_to_4" type="revolute">
    <origin rpy="0 0 0" xyz="0 0 0.009"/>
    <parent link="franka1_instrument3"/>
    <child link="franka1_instrument4"/>
    <axis xyz="0 1 0"/>
    <limit effort="12" lower="-1.5" upper="1.5" velocity="2.6100"/>
  </joint>
  <link name="franka1_tool"/>
  <joint name="franka1_instrument4_to_tool" type="fixed">
    <origin rpy="0 0 0" xyz="0 0 0.022"/>
    <parent link="franka1_instrument4"/>
    <child link="franka1_tool"/>
    <axis xyz="0 0 0"/>
  </joint>
  <link name="franka1_tool_ik"/>
  <joint name="franka1_instrument1_to_toolik" type="fixed">
    <origin rpy="-0.0117919678 0 0" xyz="0 -0.09102 0.4"/>
    <parent link="franka1_instrument1"/>
    <child link="franka1_tool_ik"/>
    <axis xyz="0 0 0"/>
  </joint>














  <joint name="world_to_robot2" type="fixed">
    <origin rpy="0 0 3.1415926" xyz="1.5 0 0"/>
    <parent link="world"/>
    <child link="panda2_link0"/>
    <axis xyz="0 0 0"/>
  </joint>
  <link name="panda2_link0">
    <visual>
      <geometry>
        <mesh filename="package://franka_description/meshes/visual/link0.dae"/>
      </geometry>
    </visual>
    <collision>
      <geometry>
        <mesh filename="package://franka_description/meshes/collision/link0.stl"/>
      </geometry>
    </collision>
  </link>
  <link name="panda2_link1">
    <visual>
      <geometry>
        <mesh filename="package://franka_description/meshes/visual/link1.dae"/>
      </geometry>
    </visual>
    <collision>
      <geometry>
        <mesh filename="package://franka_description/meshes/collision/link1.stl"/>
      </geometry>
    </collision>
  </link>
  <joint name="franka2_panda_joint1" type="revolute">
    <safety_controller k_position="100.0" k_velocity="40.0" soft_lower_limit="-2.8973" soft_upper_limit="2.8973"/>
    <origin rpy="0 0 0" xyz="0 0 0.333"/>
    <parent link="panda2_link0"/>
    <child link="panda2_link1"/>
    <axis xyz="0 0 1"/>
    <limit effort="87" lower="-2.8973" upper="2.8973" velocity="2.1750"/>
  </joint>
  <link name="panda2_link2">
    <visual>
      <geometry>
        <mesh filename="package://franka_description/meshes/visual/link2.dae"/>
      </geometry>
    </visual>
    <collision>
      <geometry>
        <mesh filename="package://franka_description/meshes/collision/link2.stl"/>
      </geometry>
    </collision>
  </link>
  <joint name="franka2_panda_joint2" type="revolute">
    <safety_controller k_position="100.0" k_velocity="40.0" soft_lower_limit="-1.7628" soft_upper_limit="1.7628"/>
    <origin rpy="-1.57079632679 0 0" xyz="0 0 0"/>
    <parent link="panda2_link1"/>
    <child link="panda2_link2"/>
    <axis xyz="0 0 1"/>
    <limit effort="87" lower="-1.7628" upper="1.7628" velocity="2.1750"/>
  </joint>
  <link name="panda2_link3">
    <visual>
      <geometry>
        <mesh filename="package://franka_description/meshes/visual/link3.dae"/>
      </geometry>
    </visual>
    <collision>
      <geometry>
        <mesh filename="package://franka_description/meshes/collision/link3.stl"/>
      </geometry>
    </collision>
  </link>
  <joint name="franka2_panda_joint3" type="revolute">
    <safety_controller k_position="100.0" k_velocity="40.0" soft_lower_limit="-2.8973" soft_upper_limit="2.8973"/>
    <origin rpy="1.57079632679 0 0" xyz="0 -0.316 0"/>
    <parent link="panda2_link2"/>
    <child link="panda2_link3"/>
    <axis xyz="0 0 1"/>
    <limit effort="87" lower="-2.8973" upper="2.8973" velocity="2.1750"/>
  </joint>
  <link name="panda2_link4">
    <visual>
      <geometry>
        <mesh filename="package://franka_description/meshes/visual/link4.dae"/>
      </geometry>
    </visual>
    <collision>
      <geometry>
        <mesh filename="package://franka_description/meshes/collision/link4.stl"/>
      </geometry>
    </collision>
  </link>
  <joint name="franka2_panda_joint4" type="revolute">
    <safety_controller k_position="100.0" k_velocity="40.0" soft_lower_limit="-3.0718" soft_upper_limit="-0.0698"/>
    <origin rpy="1.57079632679 0 0" xyz="0.0825 0 0"/>
    <parent link="panda2_link3"/>
    <child link="panda2_link4"/>
    <axis xyz="0 0 1"/>
    <limit effort="87" lower="-3.0718" upper="-0.0698" velocity="2.1750"/>
  </joint>
  <link name="panda2_link5">
    <visual>
      <geometry>
        <mesh filename="package://franka_description/meshes/visual/link5.dae"/>
      </geometry>
    </visual>
    <collision>
      <geometry>
        <mesh filename="package://franka_description/meshes/collision/link5.stl"/>
      </geometry>
    </collision>
  </link>
  <joint name="franka2_panda_joint5" type="revolute">
    <safety_controller k_position="100.0" k_velocity="40.0" soft_lower_limit="-2.8973" soft_upper_limit="2.8973"/>
    <origin rpy="-1.57079632679 0 0" xyz="-0.0825 0.384 0"/>
    <parent link="panda2_link4"/>
    <child link="panda2_link5"/>
    <axis xyz="0 0 1"/>
    <limit effort="12" lower="-2.8973" upper="2.8973" velocity="2.6100"/>
  </joint>
  <link name="panda2_link6">
    <visual>
      <geometry>
        <mesh filename="package://franka_description/meshes/visual/link6.dae"/>
      </geometry>
    </visual>
    <collision>
      <geometry>
        <mesh filename="package://franka_description/meshes/collision/link6.stl"/>
      </geometry>
    </collision>
  </link>
  <joint name="franka2_panda_joint6" type="revolute">
    <safety_controller k_position="100.0" k_velocity="40.0" soft_lower_limit="-0.0175" soft_upper_limit="3.7525"/>
    <origin rpy="1.57079632679 0 0" xyz="0 0 0"/>
    <parent link="panda2_link5"/>
    <child link="panda2_link6"/>
    <axis xyz="0 0 1"/>
    <limit effort="12" lower="-0.0175" upper="3.7525" velocity="2.6100"/>
  </joint>
  <link name="panda2_link7">
    <visual>
      <geometry>
        <mesh filename="package://franka_description/meshes/visual/link7.dae"/>
      </geometry>
    </visual>
    <collision>
      <geometry>
        <mesh filename="package://franka_description/meshes/collision/link7.stl"/>
      </geometry>
    </collision>
  </link>
  <joint name="franka2_panda_joint7" type="revolute">
    <safety_controller k_position="100.0" k_velocity="40.0" soft_lower_limit="-2.8973" soft_upper_limit="2.8973"/>
    <origin rpy="1.57079632679 0 0" xyz="0.088 0 0"/>
    <parent link="panda2_link6"/>
    <child link="panda2_link7"/>
    <axis xyz="0 0 1"/>
    <limit effort="12" lower="-2.8973" upper="2.8973" velocity="2.6100"/>
  </joint>
  <link name="panda2_link8"/>
  <joint name="franka2_panda_joint8" type="fixed">
    <origin rpy="0 0 0" xyz="0 0 0.107"/>
    <parent link="panda2_link7"/>
    <child link="panda2_link8"/>
    <axis xyz="0 0 0"/>
  </joint>
  <link name="ee2_link"/>
  <joint name="franka2_panda8_to_ee" type="fixed">
    <origin rpy="0 0 0.78539815" xyz="0 0 0"/>
    <parent link="panda2_link8"/>
    <child link="ee2_link"/>
    <axis xyz="0 0 0"/>
  </joint>
  <link name="franka2_instrument1">
    <visual>
      <geometry>
        <mesh filename="package://franka_description/meshes/instrument/instrument1.stl"/>
      </geometry>
      <material name="">
        <color rgba="1 0.93 0.54 1" />
      </material>
    </visual>
    <collision>
      <geometry>
        <mesh filename="package://franka_description/meshes/instrument/instrument1.stl"/>
      </geometry>
    </collision>
  </link>
  <joint name="franka2_ee_to_instrument1" type="fixed">
    <origin rpy="0 0 0" xyz="0 0 0"/>
    <parent link="ee2_link"/>
    <child link="franka2_instrument1"/>
    <axis xyz="0 0 0"/>
  </joint>
  <link name="franka2_instrument2">
    <visual>
      <geometry>
        <mesh filename="package://franka_description/meshes/instrument/2.stl"/>
      </geometry>
      <material name="">
        <color rgba="1 0.93 0.54 1" />
      </material>
    </visual>
    <collision>
      <geometry>
        <mesh filename="package://franka_description/meshes/instrument/2.stl"/>
      </geometry>
    </collision>
  </link>
  <joint name="franka2_instrument1_to_2" type="revolute">
    <origin rpy="-0.0117919678 0 0" xyz="0 -0.09102 0.36"/>
    <parent link="franka2_instrument1"/>
    <child link="franka2_instrument2"/>
    <axis xyz="0 0 1"/>
    <limit effort="12" lower="-3.14" upper="3.14" velocity="2.6100"/>
  </joint>
  <link name="franka2_instrument3">
    <visual>
      <geometry>
        <mesh filename="package://franka_description/meshes/instrument/3.stl"/>
      </geometry>
      <material name="">
        <color rgba="1 0.93 0.54 1" />
      </material>
    </visual>
    <collision>
      <geometry>
        <mesh filename="package://franka_description/meshes/instrument/3.stl"/>
      </geometry>
    </collision>
  </link>
  <joint name="franka2_instrument2_to_3" type="revolute">
    <origin rpy="0 0 0" xyz="0 0 0.009"/>
    <parent link="franka2_instrument2"/>
    <child link="franka2_instrument3"/>
    <axis xyz="1 0 0"/>
    <limit effort="12" lower="-1.5" upper="1.5" velocity="2.6100"/>
  </joint>
  <link name="franka2_instrument4">
    <visual>
      <geometry>
        <mesh filename="package://franka_description/meshes/instrument/4.stl"/>
      </geometry>
      <material name="">
        <color rgba="1 0.93 0.54 1" />
      </material>
    </visual>
    <collision>
      <geometry>
        <mesh filename="package://franka_description/meshes/instrument/4.stl"/>
      </geometry>
    </collision>
  </link>
  <joint name="franka2_instrument3_to_4" type="revolute">
    <origin rpy="0 0 0" xyz="0 0 0.009"/>
    <parent link="franka2_instrument3"/>
    <child link="franka2_instrument4"/>
    <axis xyz="0 1 0"/>
    <limit effort="12" lower="-1.5" upper="1.5" velocity="2.6100"/>
  </joint>
  <link name="franka2_tool"/>
  <joint name="franka2_instrument4_to_tool" type="fixed">
    <origin rpy="0 0 0" xyz="0 0 0.022"/>
    <parent link="franka2_instrument4"/>
    <child link="franka2_tool"/>
    <axis xyz="0 0 0"/>
  </joint>
  <link name="franka2_tool_ik"/>
  <joint name="franka2_instrument1_to_toolik" type="fixed">
    <origin rpy="-0.0117919678 0 0" xyz="0 -0.09102 0.4"/>
    <parent link="franka2_instrument1"/>
    <child link="franka2_tool_ik"/>
    <axis xyz="0 0 0"/>
  </joint>



</robot>

